Workbook

Sheet Instructions
A1: UI Requirements, Feedback and Suggestions Template
A2: Use this workbook to capture, prioritize and track user interface inputs for an application.
A4: How to use this template
A6: 1 | B6: Capture requirements | C6: Use the Requirements sheet to document user needs, acceptance criteria, ownership and decision status.
A7: 2 | B7: Log feedback | C7: Use the Feedback sheet to record comments, usability findings, defects, concerns and observations from users or stakeholders.
A8: 3 | B8: Track suggestions | C8: Use the Suggestions sheet to record improvement ideas and prioritize them using impact and effort.
A9: 4 | B9: Map UI scope | C9: Use the UI Inventory sheet to list screens, pages and modules so requirements can be tied back to UI areas.
A10: 5 | B10: Review summary | C10: Use the Summary sheet to view counts by status, priority, severity and UI area.
A13: Conventions
A14: • | B14: Blue text fields are intended for user input.
A15: • | B15: Black formula fields are calculated automatically.
A16: • | B16: Dropdown values can be edited on the hidden Lists sheet if your project needs different categories.
A17: • | B17: Use IDs such as REQ-001, FB-001 and SUG-001 to link related items across sheets.

Sheet Summary
A1: Summary Dashboard
A2: Automated counts based on entries in the Requirements, Feedback and Suggestions sheets.
A3: Total Requirements | C3: Open Feedback | E3: Approved Requirements | G3: Completed Items
A4: =COUNTA(Requirements!$A:$A)-1 -> 154 | C4: =COUNTIF(Feedback!$O:$O,"New")+COUNTIF(Feedback!$O:$O,"Under Review") -> 0 | E4: =COUNTIF(Requirements!$J:$J,"Approved") -> 0 | G4: =COUNTIF(Requirements!$J:$J,"Completed")+COUNTIF(Feedback!$O:$O,"Completed")+COUNTIF(Suggestions!$K:$K,"Completed") -> 0
A6: Requirements by Status | D6: Requirements by Priority | G6: UI Area Activity
A7: Status | B7: Count | D7: Priority | E7: Count | G7: UI Area | H7: Count
A8: New | B8: =COUNTIF(Requirements!$J:$J,A8) -> 0 | D8: Critical | E8: =COUNTIF(Requirements!$I:$I,D8) -> 0 | G8: Navigation | H8: =COUNTIF(Requirements!$E:$E,G8)+COUNTIF(Feedback!$E:$E,G8)+COUNTIF(Suggestions!$E:$E,G8) -> 1
A9: Under Review | B9: =COUNTIF(Requirements!$J:$J,A9) -> 0 | D9: High | E9: =COUNTIF(Requirements!$I:$I,D9) -> 0 | G9: Dashboard | H9: =COUNTIF(Requirements!$E:$E,G9)+COUNTIF(Feedback!$E:$E,G9)+COUNTIF(Suggestions!$E:$E,G9) -> 14
A10: Approved | B10: =COUNTIF(Requirements!$J:$J,A10) -> 0 | D10: Medium | E10: =COUNTIF(Requirements!$I:$I,D10) -> 8 | G10: Forms/Input | H10: =COUNTIF(Requirements!$E:$E,G10)+COUNTIF(Feedback!$E:$E,G10)+COUNTIF(Suggestions!$E:$E,G10) -> 36
A11: In Progress | B11: =COUNTIF(Requirements!$J:$J,A11) -> 0 | D11: Low | E11: =COUNTIF(Requirements!$I:$I,D11) -> 0 | G11: Search/Filter | H11: =COUNTIF(Requirements!$E:$E,G11)+COUNTIF(Feedback!$E:$E,G11)+COUNTIF(Suggestions!$E:$E,G11) -> 2
A12: Deferred | B12: =COUNTIF(Requirements!$J:$J,A12) -> 0 | G12: Workflow | H12: =COUNTIF(Requirements!$E:$E,G12)+COUNTIF(Feedback!$E:$E,G12)+COUNTIF(Suggestions!$E:$E,G12) -> 3
A13: Rejected | B13: =COUNTIF(Requirements!$J:$J,A13) -> 0 | G13: Reports/Exports | H13: =COUNTIF(Requirements!$E:$E,G13)+COUNTIF(Feedback!$E:$E,G13)+COUNTIF(Suggestions!$E:$E,G13) -> 9
A14: Completed | B14: =COUNTIF(Requirements!$J:$J,A14) -> 0 | G14: Notifications | H14: =COUNTIF(Requirements!$E:$E,G14)+COUNTIF(Feedback!$E:$E,G14)+COUNTIF(Suggestions!$E:$E,G14) -> 0
G15: User Profile | H15: =COUNTIF(Requirements!$E:$E,G15)+COUNTIF(Feedback!$E:$E,G15)+COUNTIF(Suggestions!$E:$E,G15) -> 0
G16: Admin | H16: =COUNTIF(Requirements!$E:$E,G16)+COUNTIF(Feedback!$E:$E,G16)+COUNTIF(Suggestions!$E:$E,G16) -> 0
A17: Feedback by Severity | D17: Suggestions by Status | G17: Mobile/Responsive | H17: =COUNTIF(Requirements!$E:$E,G17)+COUNTIF(Feedback!$E:$E,G17)+COUNTIF(Suggestions!$E:$E,G17) -> 0
A18: Severity | B18: Count | D18: Status | E18: Count | G18: Other | H18: =COUNTIF(Requirements!$E:$E,G18)+COUNTIF(Feedback!$E:$E,G18)+COUNTIF(Suggestions!$E:$E,G18) -> 9
A19: Critical | B19: =COUNTIF(Feedback!$H:$H,A19) -> 0 | D19: New | E19: =COUNTIF(Suggestions!$K:$K,D19) -> 0
A20: High | B20: =COUNTIF(Feedback!$H:$H,A20) -> 10 | D20: Under Review | E20: =COUNTIF(Suggestions!$K:$K,D20) -> 0
A21: Medium | B21: =COUNTIF(Feedback!$H:$H,A21) -> 17 | D21: Approved | E21: =COUNTIF(Suggestions!$K:$K,D21) -> 0
A22: Low | B22: =COUNTIF(Feedback!$H:$H,A22) -> 64 | D22: In Progress | E22: =COUNTIF(Suggestions!$K:$K,D22) -> 0
D23: Deferred | E23: =COUNTIF(Suggestions!$K:$K,D23) -> 0
D24: Rejected | E24: =COUNTIF(Suggestions!$K:$K,D24) -> 0
D25: Completed | E25: =COUNTIF(Suggestions!$K:$K,D25) -> 0

Sheet Requirements
A1: Requirements Log
A2: Capture UI requirements, user stories, acceptance criteria, ownership and status.
A4: Requirement ID | B4: Date Captured | C4: Requested By | D4: User Role | E4: UI Area | F4: Requirement | G4: Business Rationale | H4: Requirement Type | I4: Priority | J4: Status | K4: Acceptance Criteria | L4: Dependencies | M4: Owner | N4: Target Release | O4: Due Date | P4: Decision / Resolution | Q4: Notes
A5: ="REQ-00" & TEXT(ROW() - ROW(tblRequirements[[#Headers],[Requirement ID]]), "0;-0") -> REQ-001 | B5: 46245 | C5: Krishna | E5: Forms/Input | F5: Change the button name "Browse S3" in the metadata mapping form | H5: Usability | I5: Medium
A6: ="REQ-00" & TEXT(ROW() - ROW(tblRequirements[[#Headers],[Requirement ID]]), "0;-0") -> REQ-002 | B6: 46245 | C6: Krishna | E6: Forms/Input | F6: The Protocol and Trial design form hada protocol uplaoded for study 671-6974 and the trial domains were populated. It allowed me to add another protocol amendment. when i click the "Extract TDM" the trial domains are not refreshed with the amendment | H6: Data/Reporting | I6: Medium
A7: ="REQ-00" & TEXT(ROW() - ROW(tblRequirements[[#Headers],[Requirement ID]]), "0;-0") -> REQ-003 | B7: 46258 | C7: Gopal | E7: Buttons | F7: add domains class under TOC botton in mapping spec | H7: Usability | I7: Medium
A8: ="REQ-00" & TEXT(ROW() - ROW(tblRequirements[[#Headers],[Requirement ID]]), "0;-0") -> REQ-004 | B8: 46259 | C8: Karthik | E8: Forms/Input | F8: Protocol/TDM - We need to add TD, TM domains | H8: Data/Reporting | I8: Medium | P8: Team will add them
A9: ="REQ-00" & TEXT(ROW() - ROW(tblRequirements[[#Headers],[Requirement ID]]), "0;-0") -> REQ-005 | B9: 46259 | C9: Karthik | E9: Forms/Input | F9: Metadata mapping: When an ALS document is uploaded, the system reads the file. Could we add a display section, similar to the Uploaded Files list, that shows the name of the source raw metadata file? This would help trace which metadata file was used during CRF migrations and amendments. | H9: Data/Reporting | I9: Medium | P9: Team will add them | Q9: ALS name to appear
A10: ="REQ-00" & TEXT(ROW() - ROW(tblRequirements[[#Headers],[Requirement ID]]), "0;-0") -> REQ-006 | B10: 46259 | C10: Karthik | E10: Forms/Input | F10: When we upload multiple protocols, can we have an option to select which protocol has to be used for extracting TD's | H10: Data/Reporting | I10: Medium | P10: Team will restrict to add only one version of protocol
A11: ="REQ-00" & TEXT(ROW() - ROW(tblRequirements[[#Headers],[Requirement ID]]), "0;-0") -> REQ-007 | B11: 46261 | C11: Karthik | E11: Buttons | F11: I have mapped AEYN to SUPPAE and approved it. Can we build a feature to revert the decision ? Can we have an option to review first and then approve instead of build & approve? | Q11: Will fix it
A12: ="REQ-00" & TEXT(ROW() - ROW(tblRequirements[[#Headers],[Requirement ID]]), "0;-0") -> REQ-008 | B12: 46261 | C12: Karthik | E12: Reports/Exports | F12: When we export, the file name is "mapping_spec_a9e53f52-fa0a-4b31-a542-643c29a3ae28". Could we have it started with study number , taskname, date, version X.O | H12: Data/Reporting | I12: Medium | Q12: will check
A13: ="REQ-00" & TEXT(ROW() - ROW(tblRequirements[[#Headers],[Requirement ID]]), "0;-0") -> REQ-009 | B13: 46261 | C13: Karthik | E13: Forms/Input | F13: For unmapped variables, it says one per line. Could we have the unmapped variables pulled from Metadata mapping tab instead of manual entry. AI mapping is not working - says 0 suggestions. | H13: Workflow | I13: Medium | Q13: will check
A14: ="REQ-00" & TEXT(ROW() - ROW(tblRequirements[[#Headers],[Requirement ID]]), "0;-0") -> REQ-0010 | B14: 46261 | C14: Karthik | E14: Forms/Input | F14: When we create new study - should we say what Gilead mapping spec to use? as we will have two versions of 3.4 next year ? | Q14: Will add in metadata mapping
A15: ="REQ-00" & TEXT(ROW() - ROW(tblRequirements[[#Headers],[Requirement ID]]), "0;-0") -> REQ-0011 | B15: 46261 | C15: Karthik | E15: Forms/Input | F15: Can we have option to select datasets from ALS ? For interim analysis, we might not need all datasets to be mapped | Q15: local version is already updated to fix this.
A16: ="REQ-00" & TEXT(ROW() - ROW(tblRequirements[[#Headers],[Requirement ID]]), "0;-0") -> REQ-0012 | B16: 46267 | C16: Karthik | E16: Dashboard | F16: Currently, we are seeing all studies in the dashboard. When we deploy, will the users see all studies or their own studies ? if all studies, can we add a feature to favorite them or like my studies option ? | Q16: Neel is aware of it and will check
A17: ="REQ-00" & TEXT(ROW() - ROW(tblRequirements[[#Headers],[Requirement ID]]), "0;-0") -> REQ-0013 | B17: 46267 | C17: Karthik | E17: Dashboard | F17: Build/Domain build: Can we have a column which states "like mapping from core spec: No change allowed". Otherwise, i need to look into all rows and verify | Q17: Neel will add confidence column
A18: ="REQ-00" & TEXT(ROW() - ROW(tblRequirements[[#Headers],[Requirement ID]]), "0;-0") -> REQ-0014 | B18: 46268 | C18: Karthik | E18: Dashboard | F18: Metadata mapping + AI mapping into Metadata mapping | Q18: Other function groups requested to have it as separate column
A19: ="REQ-00" & TEXT(ROW() - ROW(tblRequirements[[#Headers],[Requirement ID]]), "0;-0") -> REQ-0015 | B19: 46268 | C19: Karthik | E19: Dashboard | F19: Mapping spec: Can we have options whether to present all domains from Core mapping spec or select domains from core mapping spec to include in the final mapping spec? When the rawplus is mapped to new LABCT, we have additional domains that can be only seen from rawplus and metdata file cannot catch it. | Q19: in mapping spec, TOC column will lists all the domains and user can select
A20: ="REQ-00" & TEXT(ROW() - ROW(tblRequirements[[#Headers],[Requirement ID]]), "0;-0") -> REQ-0016 | B20: 46268 | C20: Karthik | E20: Dashboard | F20: Mapping spec: Can we keep a feature to add custom domain based on the class? Just an enhancement. | Q20: Neel will check and add it
A21: ="REQ-00" & TEXT(ROW() - ROW(tblRequirements[[#Headers],[Requirement ID]]), "0;-0") -> REQ-0017 | B21: 46268 | C21: Karthik | E21: Dashboard | F21: Autobuild: When we add a column active Y/N, can we also add an option to select all | Q21: Neel will check and add it
A22: ="REQ-00" & TEXT(ROW() - ROW(tblRequirements[[#Headers],[Requirement ID]]), "0;-0") -> REQ-0018 | B22: 46268 | C22: Karthik | E22: Dashboard | F22: Domain build: Can we add a column like "No change allowed, mapped from Core spec", so that user will have few variables to pay attention. | Q22: Neel will add confidence column
A23: ="REQ-00" & TEXT(ROW() - ROW(tblRequirements[[#Headers],[Requirement ID]]), "0;-0") -> REQ-0019 | B23: 46268 | C23: Karthik | E23: Mapping spec | F23: same as above. | Q23: Neel will add confidence column
A24: ="REQ-00" & TEXT(ROW() - ROW(tblRequirements[[#Headers],[Requirement ID]]), "0;-0") -> REQ-0020
A25: ="REQ-00" & TEXT(ROW() - ROW(tblRequirements[[#Headers],[Requirement ID]]), "0;-0") -> REQ-0021
A26: ="REQ-00" & TEXT(ROW() - ROW(tblRequirements[[#Headers],[Requirement ID]]), "0;-0") -> REQ-0022
A27: ="REQ-00" & TEXT(ROW() - ROW(tblRequirements[[#Headers],[Requirement ID]]), "0;-0") -> REQ-0023
A28: ="REQ-00" & TEXT(ROW() - ROW(tblRequirements[[#Headers],[Requirement ID]]), "0;-0") -> REQ-0024
A29: ="REQ-00" & TEXT(ROW() - ROW(tblRequirements[[#Headers],[Requirement ID]]), "0;-0") -> REQ-0025
A30: ="REQ-00" & TEXT(ROW() - ROW(tblRequirements[[#Headers],[Requirement ID]]), "0;-0") -> REQ-0026
A31: ="REQ-00" & TEXT(ROW() - ROW(tblRequirements[[#Headers],[Requirement ID]]), "0;-0") -> REQ-0027
A32: ="REQ-00" & TEXT(ROW() - ROW(tblRequirements[[#Headers],[Requirement ID]]), "0;-0") -> REQ-0028
A33: ="REQ-00" & TEXT(ROW() - ROW(tblRequirements[[#Headers],[Requirement ID]]), "0;-0") -> REQ-0029
A34: ="REQ-00" & TEXT(ROW() - ROW(tblRequirements[[#Headers],[Requirement ID]]), "0;-0") -> REQ-0030
A35: ="REQ-00" & TEXT(ROW() - ROW(tblRequirements[[#Headers],[Requirement ID]]), "0;-0") -> REQ-0031
... A154: ="REQ-00" & TEXT(ROW() - ROW(tblRequirements[[#Headers],[Requirement ID]]), "0;-0") -> REQ-00150
A155: ="REQ-00" & TEXT(ROW() - ROW(tblRequirements[[#Headers],[Requirement ID]]), "0;-0") -> REQ-00151 | B155: 46261 | C155: Krishna | E155: Forms/Input | F155: Mapping spec: Under TOC - can we have active Y/N, so user can decide what domains has to be generated for that analysis ? | Q155: local version is already updated to fix this.
A156: ="REQ-00" & TEXT(ROW() - ROW(tblRequirements[[#Headers],[Requirement ID]]), "0;-0") -> REQ-00152

Sheet Feedback
A1: Feedback Log
A2: Record feedback from user research, usability testing, stakeholder reviews and support channels.
A4: Feedback ID | B4: Date | C4: Source / Session | D4: User / Role | E4: UI Area | F4: Screen / Module | G4: Feedback Type | H4: Severity | I4: Feedback Summary | J4: Current Experience | K4: Expected Experience | L4: Evidence / Link | M4: Action Needed | N4: Owner | O4: Status | P4: Related Requirement ID | Q4: Resolution Notes
A5: ="FB-00" & TEXT(ROW() - ROW(tblFeedback[[#Headers],[Feedback ID]]), "0;-0") -> FB-001 | B5: 46245 | C5: Internal Review | D5: Krishna | E5: Forms/Input | F5: Metadata mapping | G5: Question | H5: High | I5: The button browse s3 has folders with names that are not meaningful to select the rawdata or ALS files for the study
A6: ="FB-00" & TEXT(ROW() - ROW(tblFeedback[[#Headers],[Feedback ID]]), "0;-0") -> FB-002
A7: ="FB-00" & TEXT(ROW() - ROW(tblFeedback[[#Headers],[Feedback ID]]), "0;-0") -> FB-003 | B7: 46252 | C7: Internal Review | D7: Gopal | E7: Other | F7: Node Graph | G7: Enhancement | H7: Medium | I7: some of the graph fields aren't showing up properly like literal is linking to studyid and Domain. we need to check all the variables for accuracy. can we put Protocol as origin for STUDYID in all the SDTM domains. Even for sequence, we should something like stuydid.
A8: ="FB-00" & TEXT(ROW() - ROW(tblFeedback[[#Headers],[Feedback ID]]), "0;-0") -> FB-004 | B8: 46252 | C8: Internal Review | D8: Gopal | E8: Other | F8: Node Graph | G8: Enhancement | H8: Medium | I8: same like above .devired is linked to SUPP variables.
A9: ="FB-00" & TEXT(ROW() - ROW(tblFeedback[[#Headers],[Feedback ID]]), "0;-0") -> FB-005 | B9: 46252 | C9: Internal Review | D9: Gopal | E9: Other | F9: Node Graph | G9: Enhancement | H9: Medium | I9: can we change the COND to CODE in the graph node for derived variables to avoid confusion.
A10: ="FB-00" & TEXT(ROW() - ROW(tblFeedback[[#Headers],[Feedback ID]]), "0;-0") -> FB-006 | B10: 46258 | C10: Internal Review | D10: Gopal | E10: Other | F10: Metadata mapping | G10: Issue | H10: High | I10: looks like administrative datasets like cov_pk, ba_pk_inv are being mapped we need to drop them.
A11: ="FB-00" & TEXT(ROW() - ROW(tblFeedback[[#Headers],[Feedback ID]]), "0;-0") -> FB-007 | B11: 46258 | C11: Internal Review | D11: Gopal | E11: Other | F11: Metadata mapping | G11: Issue | H11: Medium | I11: right now sas length has decimal value showing up. can we take out the decimal from SAS length. same for KEY SEQ column
A12: ="FB-00" & TEXT(ROW() - ROW(tblFeedback[[#Headers],[Feedback ID]]), "0;-0") -> FB-008 | B12: 46258 | C12: Internal Review | D12: Gopal | E12: Buttons | F12: Build and output | G12: Issue | H12: High | I12: Auto build should be run only after the syntnetic data be enabled in order to generate outputs right now the autobuild is showing a zero domains. check for the dependencies.
A13: ="FB-00" & TEXT(ROW() - ROW(tblFeedback[[#Headers],[Feedback ID]]), "0;-0") -> FB-009 | B13: 46258 | C13: Internal Review | D13: Gopal | F13: delivery package | G13: Issue | H13: High | I13: right now in the data package mapping spefication is not included can we add it as output along with SAS programs for download
A14: ="FB-00" & TEXT(ROW() - ROW(tblFeedback[[#Headers],[Feedback ID]]), "0;-0") -> FB-0010 | B14: 46258 | C14: Internal Review | D14: Gopal | E14: Mapping spec | F14: implemented SAS CODE | G14: Issue | H14: Medium | I14: implemented SAS code is missing for AEACN
A15: ="FB-00" & TEXT(ROW() - ROW(tblFeedback[[#Headers],[Feedback ID]]), "0;-0") -> FB-0011 | B15: 46258 | C15: Internal Review | D15: Gopal | E15: Mapping spec | F15: variable | G15: Issue | H15: Low | I15: where this varaible SPDEVID from come in EG domains
A16: ="FB-00" & TEXT(ROW() - ROW(tblFeedback[[#Headers],[Feedback ID]]), "0;-0") -> FB-0012 | B16: 46258 | C16: Internal Review | D16: Gopal | E16: AI mapping | G16: Question | H16: Low | I16: now I dont see any unmapped variablles in AI mapping. will they be coming up once we coonect to AI models?
A17: ="FB-00" & TEXT(ROW() - ROW(tblFeedback[[#Headers],[Feedback ID]]), "0;-0") -> FB-0013 | B17: 46258 | C17: Internal Review | D17: Gopal | E17: mapping spec | F17: TOC | G17: Issue | H17: High | I17: some domains are missing labels in the TOC sheet
A18: ="FB-00" & TEXT(ROW() - ROW(tblFeedback[[#Headers],[Feedback ID]]), "0;-0") -> FB-0014 | B18: 46258 | C18: Internal Review | D18: Gopal | E18: mapping spec | F18: TOC | G18: Issue | H18: High | I18: Drug accountability label should be changed to the latest label.
A19: ="FB-00" & TEXT(ROW() - ROW(tblFeedback[[#Headers],[Feedback ID]]), "0;-0") -> FB-0015 | B19: 46259 | C19: Internal Review | D19: Karthik | E19: Dashboard | F19: Study Details | G19: Usability | H19: Low | I19: Currently owner info is displayed as Gilead email address and it is truncated (when we create new program), overlapped on created field (when we create standalone) | Q19: Neel is aware of it
A20: ="FB-00" & TEXT(ROW() - ROW(tblFeedback[[#Headers],[Feedback ID]]), "0;-0") -> FB-0016 | B20: 46259 | C20: Internal Review | D20: Karthik | E20: Navigation | F20: Protocol/TDM | G20: Issue | H20: Low | I20: Browse files option is not working, it takes back to main screen | Q20: Issue is only from my end.
A21: ="FB-00" & TEXT(ROW() - ROW(tblFeedback[[#Headers],[Feedback ID]]), "0;-0") -> FB-0017 | B21: 46259 | C21: Internal Review | D21: Karthik | E21: Reports/Exports | F21: Protocol/TDM | G21: Issue | H21: Low | I21: 1) Do we need add column to trial designs ? 2) I have added some rows, YZ column and downloaded to CSV. CSV file has retained the rows but not column (YZ)
A22: ="FB-00" & TEXT(ROW() - ROW(tblFeedback[[#Headers],[Feedback ID]]), "0;-0") -> FB-0018 | B22: 46259 | C22: Internal Review | D22: Karthik | E22: Forms/Input | F22: Protocol/TDM | G22: Issue | H22: Low | I22: TA/TE elements are not in sync.
A23: ="FB-00" & TEXT(ROW() - ROW(tblFeedback[[#Headers],[Feedback ID]]), "0;-0") -> FB-0019 | B23: 46259 | C23: Internal Review | D23: Karthik | E23: Forms/Input | F23: Protocol/TDM | G23: Issue | H23: Low | I23: Order of variables in details panel is not same as left panel (Trial design variables order) | Q23: Neel will fix it
A24: ="FB-00" & TEXT(ROW() - ROW(tblFeedback[[#Headers],[Feedback ID]]), "0;-0") -> FB-0020 | B24: 46259 | C24: Internal Review | D24: Karthik | E24: Forms/Input | F24: Protocol/TDM | G24: Issue | H24: Low | I24: For TV - TVSTRL, ENRL is missing. For TS - TSGRPID, TSVAL1, 2, TSVALNF, TSVALCD, TSVCDREF, TSVCDVER are missing. | Q24: Neel will check and update it
A25: ="FB-00" & TEXT(ROW() - ROW(tblFeedback[[#Headers],[Feedback ID]]), "0;-0") -> FB-0021 | B25: 46259 | C25: Internal Review | D25: Karthik | E25: Forms/Input | F25: Protocol/TDM | G25: Issue | H25: Low | I25: SOA - Flow diagram is tiny to read. It is generalized and not read correctly (Has Tumor assessment when protocol doesnt have it) Have Matrix in 2 places. Flow says - flow diagram is coming soon. Flow diagram option is also present just above the assessment table. | Q25: Neel is aware of it
A26: ="FB-00" & TEXT(ROW() - ROW(tblFeedback[[#Headers],[Feedback ID]]), "0;-0") -> FB-0022 | B26: 46261 | C26: Internal Review | D26: Karthik | E26: Forms/Input | F26: Metadata mapping | G26: Issue | H26: Low | I26: Metadata mapping: Could not read XLS metadata file (97-2003 excel). Gave this error - could not read metadata file: Missing optional dependency 'xlrd'. Install xlrd >= 2.0.1 for xls Excel support Use pip or conda to install xlrd. What is parquet ? | Q26: will remove parquet and check for XLS format
A27: ="FB-00" & TEXT(ROW() - ROW(tblFeedback[[#Headers],[Feedback ID]]), "0;-0") -> FB-0023 | B27: 46261 | C27: Internal Review | D27: Karthik | E27: Forms/Input | F27: Metadata mapping | G27: Issue | H27: Low | I27: I uploaded ALS in XLSX format and Run mapping gave me "HTTP 500" error.
A28: ="FB-00" & TEXT(ROW() - ROW(tblFeedback[[#Headers],[Feedback ID]]), "0;-0") -> FB-0024 | B28: 46261 | C28: Internal Review | D28: Kai | E28: Programs/Protocol | G28: Enhancement | H28: Low | I28: Shows the partial value as "GS-US-XXX", please increase the length to display the full value of the protocol #.
A29: ="FB-00" & TEXT(ROW() - ROW(tblFeedback[[#Headers],[Feedback ID]]), "0;-0") -> FB-0025 | B29: 46261 | C29: Internal Review | D29: Karthik | E29: Forms/Input | F29: Metadata mapping | G29: Issue | H29: Low | I29: STATUS: For variables that are mapped, do we need the "Mark not needed" ? If we need this option, can it ask for approval before excluding. | Q29: Will work around it
A30: ="FB-00" & TEXT(ROW() - ROW(tblFeedback[[#Headers],[Feedback ID]]), "0;-0") -> FB-0026 | B30: 46261 | C30: Internal Review | D30: Kai | E30: Programs/Protocol | F30: Protocol/TDM | G30: Issue | H30: Low | I30: Element shows the general TRT value but the actual treatment value.
A31: ="FB-00" & TEXT(ROW() - ROW(tblFeedback[[#Headers],[Feedback ID]]), "0;-0") -> FB-0027 | B31: 46261 | C31: Internal Review | D31: Karthik | E31: Forms/Input | F31: Metadata mapping | G31: Issue | H31: Low | I31: The hyperlink from metadata mapping to Mapping spec, doesnt give a edit option. Incase, if we need to update the labels, origin, keyseq. For example: AEACN1, 2 label has to be updated in SUPPAE. | Q31: Will check and fix it
A32: ="FB-00" & TEXT(ROW() - ROW(tblFeedback[[#Headers],[Feedback ID]]), "0;-0") -> FB-0028 | B32: 46261 | C32: Internal Review | D32: Kai | E32: Programs/Protocol | F32: Protocol/TDM | G32: Issue | H32: Medium | I32: ETCD, ELEMENT values should be identical in TA and TE domains.
A33: ="FB-00" & TEXT(ROW() - ROW(tblFeedback[[#Headers],[Feedback ID]]), "0;-0") -> FB-0029 | B33: 46261 | C33: Internal Review | D33: Karthik | E33: Forms/Input | F33: Mapping spec | G33: Issue | H33: Low | I33: I added AEYN to SUPPAE. In mapping spec, the origin is displayed as "CRF" instead of "Collected|Investigator" and action as "SUPP" with missing XML Type, Length. | Q33: Will check and fix it
A34: ="FB-00" & TEXT(ROW() - ROW(tblFeedback[[#Headers],[Feedback ID]]), "0;-0") -> FB-0030 | B34: 46261 | C34: Internal Review | D34: Karthik | E34: Forms/Input | F34: Metadata mapping | G34: Issue | H34: Low | I34: AETERM, AESER has missing method/source. While other CRF fields has "Core Spec"
A35: ="FB-00" & TEXT(ROW() - ROW(tblFeedback[[#Headers],[Feedback ID]]), "0;-0") -> FB-0031 | B35: 46261 | C35: Internal Review | D35: Karthik | E35: Forms/Input | F35: Node Graph | G35: Issue | H35: Low | I35: Node Graph: Lineage is not mapping correctly for some of the variables. EPOCH is not pointed to AESTDTC. | Q35: Neel is aware of it
A36: ="FB-00" & TEXT(ROW() - ROW(tblFeedback[[#Headers],[Feedback ID]]), "0;-0") -> FB-0032 | B36: 46261 | C36: Internal Review | D36: Karthik | E36: Forms/Input | F36: Node Graph | G36: Issue | H36: Low | I36: Options like COPY, CONSTANT, SEQ, DERIVED, OTHER - when we click on COPY, it deselect records that are assigned and shows other records. Same for other options. Can we update to reflect the selected option. | Q36: Neel is aware of it
A37: ="FB-00" & TEXT(ROW() - ROW(tblFeedback[[#Headers],[Feedback ID]]), "0;-0") -> FB-0033 | B37: 46261 | C37: Internal Review | D37: Karthik | E37: Forms/Input | F37: Mapping spec | G37: Issue | H37: Low | I37: Key seq, SAS length is representing value in XX.0 | Q37: Neel is aware of it
A38: ="FB-00" & TEXT(ROW() - ROW(tblFeedback[[#Headers],[Feedback ID]]), "0;-0") -> FB-0034 | B38: 46261 | C38: Internal Review | D38: Karthik | E38: Buttons | F38: Annotated CRF | G38: Issue | H38: Low | I38: We have 2 sections to upload CRF | Q38: Neel is aware of it
A39: ="FB-00" & TEXT(ROW() - ROW(tblFeedback[[#Headers],[Feedback ID]]), "0;-0") -> FB-0035 | B39: 46261 | C39: Internal Review | D39: Karthik | E39: Buttons | F39: Annotated CRF | G39: Issue | H39: Low | I39: I tried to upload blank CRF, it ended up as "HTTP 500" error and didnt upload the file. | Q39: Connection issue.
A40: ="FB-00" & TEXT(ROW() - ROW(tblFeedback[[#Headers],[Feedback ID]]), "0;-0") -> FB-0036 | B40: 46261 | C40: Internal Review | D40: Karthik | E40: Dashboard | F40: Reference | G40: Concern | H40: Low | I40: Version: it has latest, 3.3. Instead of latest, can we specify what mapping spec is used? | Q40: Neel is aware of it
A41: ="FB-00" & TEXT(ROW() - ROW(tblFeedback[[#Headers],[Feedback ID]]), "0;-0") -> FB-0037 | B41: 46261 | C41: Internal Review | D41: Karthik | E41: Dashboard | F41: Reference | G41: Concern | H41: Low | I41: Any chances of including provisional spec ? | Q41: Connecting to spec store is the fix. Neel to add more options/questions before Run mapping.
...

Sheet Suggestions
A1: Suggestions Log
A2: Capture improvement ideas and prioritize them using impact and effort.
A4: Suggestion ID | B4: Date | C4: Suggested By | D4: User Role / Persona | E4: UI Area | F4: Suggestion | G4: Expected Benefit | H4: Impact | I4: Effort | J4: Priority Score | K4: Status | L4: Owner | M4: Related Requirement ID | N4: Notes
A5: ="SUG-00" & TEXT(ROW() - ROW(tblSuggestions[[#Headers],[Suggestion ID]]), "0;-0") -> SUG-001 | B5: 46245 | C5: Gopal | F5: Can we change the view of the domains to be consistent with our SDTM mapping spec. right now when I click on domain its showing ROLE as first column.
A6: ="SUG-00" & TEXT(ROW() - ROW(tblSuggestions[[#Headers],[Suggestion ID]]), "0;-0") -> SUG-002 | B6: 46255 | C6: Gopal | F6: upload the core Virology mapping specifications
A7: ="SUG-00" & TEXT(ROW() - ROW(tblSuggestions[[#Headers],[Suggestion ID]]), "0;-0") -> SUG-003 | B7: 46258 | C7: Gopal | E7: Diff vs Reference Spec | F7: DIFf vs reference spec in design mapping tab only showing the wording (Compare your mapped spec against the CDISC standard reference). can we also add GCDS standards here | J7: =IF($F7="","",IF($H7="High",3,IF($H7="Medium",2,IF($H7="Low",1,0)))+IF($I7="Low",3,IF($I7="Medium",2,IF($I7="High",1,0)))) -> 0
A8: ="SUG-00" & TEXT(ROW() - ROW(tblSuggestions[[#Headers],[Suggestion ID]]), "0;-0") -> SUG-004 | B8: 46258 | C8: Gopal | E8: AUTO BUILD | F8: Build every SDTM domain from the mapping spec + raw source data. Can we change this to raw meta data instead? | J8: =IF($F8="","",IF($H8="High",3,IF($H8="Medium",2,IF($H8="Low",1,0)))+IF($I8="Low",3,IF($I8="Medium",2,IF($I8="High",1,0)))) -> 0
A9: ="SUG-00" & TEXT(ROW() - ROW(tblSuggestions[[#Headers],[Suggestion ID]]), "0;-0") -> SUG-005 | B9: 46258 | C9: Gopal | E9: Mapping Spec | F9: its better to keep the implemented SAS code blank for the variables when they are dropped. | J9: =IF($F9="","",IF($H9="High",3,IF($H9="Medium",2,IF($H9="Low",1,0)))+IF($I9="Low",3,IF($I9="Medium",2,IF($I9="High",1,0)))) -> 0
A10: ="SUG-00" & TEXT(ROW() - ROW(tblSuggestions[[#Headers],[Suggestion ID]]), "0;-0") -> SUG-006 | B10: 46258 | C10: Gopal | E10: mapping spec/TOC | F10: should we display all the SDTM domains to be consistent with our standard mapping spec instead of what just mapped for our study? | J10: =IF($F10="","",IF($H10="High",3,IF($H10="Medium",2,IF($H10="Low",1,0)))+IF($I10="Low",3,IF($I10="Medium",2,IF($I10="High",1,0)))) -> 0
A11: ="SUG-00" & TEXT(ROW() - ROW(tblSuggestions[[#Headers],[Suggestion ID]]), "0;-0") -> SUG-007 | B11: 46258 | C11: Gopal | E11: Protocol/TDM | F11: can we change the display of variable columns in the trial domains to be consistent with our mapping specification | J11: =IF($F11="","",IF($H11="High",3,IF($H11="Medium",2,IF($H11="Low",1,0)))+IF($I11="Low",3,IF($I11="Medium",2,IF($I11="High",1,0)))) -> 0
A12: ="SUG-00" & TEXT(ROW() - ROW(tblSuggestions[[#Headers],[Suggestion ID]]), "0;-0") -> SUG-008 | B12: 46258 | C12: Gopal | E12: Protocol/TDM:schedule of activities | F12: flow chart for schedule of activities is hard to see, can we check if can add an option to zoom in? | J12: =IF($F12="","",IF($H12="High",3,IF($H12="Medium",2,IF($H12="Low",1,0)))+IF($I12="Low",3,IF($I12="Medium",2,IF($I12="High",1,0)))) -> 0
A13: ="SUG-00" & TEXT(ROW() - ROW(tblSuggestions[[#Headers],[Suggestion ID]]), "0;-0") -> SUG-009 | B13: 46258 | C13: Gopal | E13: Protocol/TDM:schedule of activities | F13: assesment to domains are not mapped propely to the domains | J13: =IF($F13="","",IF($H13="High",3,IF($H13="Medium",2,IF($H13="Low",1,0)))+IF($I13="Low",3,IF($I13="Medium",2,IF($I13="High",1,0)))) -> 0
A14: ="SUG-00" & TEXT(ROW() - ROW(tblSuggestions[[#Headers],[Suggestion ID]]), "0;-0") -> SUG-0010 | B14: 46259 | C14: Karthik | E14: Dashboard | F14: When we create a new study, can we have a small description on when to create New program and Standalone
A15: ="SUG-00" & TEXT(ROW() - ROW(tblSuggestions[[#Headers],[Suggestion ID]]), "0;-0") -> SUG-0011 | B15: 46259 | C15: Karthik | E15: Protocol/TDM | F15: Currently add row - adds rows to the bottom, is there any flexibility to add in between too? if we need to add any element it will be useful. | J15: =IF($F15="","",IF($H15="High",3,IF($H15="Medium",2,IF($H15="Low",1,0)))+IF($I15="Low",3,IF($I15="Medium",2,IF($I15="High",1,0)))) -> 0
A16: ="SUG-00" & TEXT(ROW() - ROW(tblSuggestions[[#Headers],[Suggestion ID]]), "0;-0") -> SUG-0012 | B16: 46259 | C16: Karthik | E16: Protocol/TDM | F16: Extract option has TDM, SAP, TOC. Do we need SAP, TOC here ? | J16: =IF($F16="","",IF($H16="High",3,IF($H16="Medium",2,IF($H16="Low",1,0)))+IF($I16="Low",3,IF($I16="Medium",2,IF($I16="High",1,0)))) -> 0
A17: ="SUG-00" & TEXT(ROW() - ROW(tblSuggestions[[#Headers],[Suggestion ID]]), "0;-0") -> SUG-0013 | B17: 46259 | C17: Karthik | E17: Protocol/TDM | F17: When edit mode is off- could the cell be locked? Currently, changes are disabled, but clicking on the cell still highlights it as though edit mode is active. | J17: =IF($F17="","",IF($H17="High",3,IF($H17="Medium",2,IF($H17="Low",1,0)))+IF($I17="Low",3,IF($I17="Medium",2,IF($I17="High",1,0)))) -> 0
A18: ="SUG-00" & TEXT(ROW() - ROW(tblSuggestions[[#Headers],[Suggestion ID]]), "0;-0") -> SUG-0014 | B18: 46259 | C18: Karthik | E18: Protocol/TDM | F18: In column reference - could we also show the other attributes like Type, Codelist, CDISC core (Req, Exp, Perm) | J18: =IF($F18="","",IF($H18="High",3,IF($H18="Medium",2,IF($H18="Low",1,0)))+IF($I18="Low",3,IF($I18="Medium",2,IF($I18="High",1,0)))) -> 0
A19: ="SUG-00" & TEXT(ROW() - ROW(tblSuggestions[[#Headers],[Suggestion ID]]), "0;-0") -> SUG-0015 | B19: 46261 | C19: Karthik | E19: Mapping spec | F19: Can we have the columns aligned with the order of columns from mapping spec. Currently, label is the 3rd column and Variable is the 12th. | J19: =IF($F19="","",IF($H19="High",3,IF($H19="Medium",2,IF($H19="Low",1,0)))+IF($I19="Low",3,IF($I19="Medium",2,IF($I19="High",1,0)))) -> 0
A20: ="SUG-00" & TEXT(ROW() - ROW(tblSuggestions[[#Headers],[Suggestion ID]]), "0;-0") -> SUG-0016 | B20: 46261 | C20: Karthik | E20: Mapping spec | F20: For mapping rule, we have wrap/unwrap option at the end of column. It works but the width of the column doesnt change. | J20: =IF($F20="","",IF($H20="High",3,IF($H20="Medium",2,IF($H20="Low",1,0)))+IF($I20="Low",3,IF($I20="Medium",2,IF($I20="High",1,0)))) -> 0
A21: ="SUG-00" & TEXT(ROW() - ROW(tblSuggestions[[#Headers],[Suggestion ID]]), "0;-0") -> SUG-0017 | B21: 46261 | C21: Karthik | E21: Mapping spec | F21: The double headed arrow appears (when we hover to the header) but it is not resizing the column | J21: =IF($F21="","",IF($H21="High",3,IF($H21="Medium",2,IF($H21="Low",1,0)))+IF($I21="Low",3,IF($I21="Medium",2,IF($I21="High",1,0)))) -> 0
A22: ="SUG-00" & TEXT(ROW() - ROW(tblSuggestions[[#Headers],[Suggestion ID]]), "0;-0") -> SUG-0018 | B22: 46261 | C22: Karthik | E22: Mapping spec | F22: Is it possible to freeze a column like variable column, so we can see the corresponding columns? or add hide columns option ? | J22: =IF($F22="","",IF($H22="High",3,IF($H22="Medium",2,IF($H22="Low",1,0)))+IF($I22="Low",3,IF($I22="Medium",2,IF($I22="High",1,0)))) -> 0
A23: ="SUG-00" & TEXT(ROW() - ROW(tblSuggestions[[#Headers],[Suggestion ID]]), "0;-0") -> SUG-0019 | B23: 46261 | C23: Karthik | E23: Mapping spec | F23: UNMAPPED option: AETERM is mapped in metadata mapping but in mapping spec it shows under unmapped. Can we keep MEDDRA terms as mapped too ? | J23: =IF($F23="","",IF($H23="High",3,IF($H23="Medium",2,IF($H23="Low",1,0)))+IF($I23="Low",3,IF($I23="Medium",2,IF($I23="High",1,0)))) -> 0
A24: ="SUG-00" & TEXT(ROW() - ROW(tblSuggestions[[#Headers],[Suggestion ID]]), "0;-0") -> SUG-0020 | B24: 46261 | C24: Karthik | E24: Metadata mapping | F24: For unmapped variables, actions show as "route". Can we have any alternate word for it ? | J24: =IF($F24="","",IF($H24="High",3,IF($H24="Medium",2,IF($H24="Low",1,0)))+IF($I24="Low",3,IF($I24="Medium",2,IF($I24="High",1,0)))) -> 0
A25: ="SUG-00" & TEXT(ROW() - ROW(tblSuggestions[[#Headers],[Suggestion ID]]), "0;-0") -> SUG-0021 | B25: 46261 | C25: Karthik | E25: Mapping spec | F25: TOC: Has columns for Mapped, Total. Can we add Unmapped columns count ? | J25: =IF($F25="","",IF($H25="High",3,IF($H25="Medium",2,IF($H25="Low",1,0)))+IF($I25="Low",3,IF($I25="Medium",2,IF($I25="High",1,0)))) -> 0
A26: ="SUG-00" & TEXT(ROW() - ROW(tblSuggestions[[#Headers],[Suggestion ID]]), "0;-0") -> SUG-0022 | B26: 46261 | C26: Karthik | E26: Mapping spec | F26: AE tab: For the filter fields, can we add "Missing" as an option. So, it is easy to filter for review and make changes. | J26: =IF($F26="","",IF($H26="High",3,IF($H26="Medium",2,IF($H26="Low",1,0)))+IF($I26="Low",3,IF($I26="Medium",2,IF($I26="High",1,0)))) -> 0
... A28: ="SUG-00" & TEXT(ROW() - ROW(tblSuggestions[[#Headers],[Suggestion ID]]), "0;-0") -> SUG-0024 | B28: 46265 | C28: Karthik | E28: Mapping spec | F28: History: Is it possible to maintain the history by domain? Currently, all the hsitory is logged by version numbers, how do we trace the changes made for each domain ? | J28: =IF($F28="","",IF($H28="High",3,IF($H28="Medium",2,IF($H28="Low",1,0)))+IF($I28="Low",3,IF($I28="Medium",2,IF($I28="High",1,0)))) -> 0
A29: ="SUG-00" & TEXT(ROW() - ROW(tblSuggestions[[#Headers],[Suggestion ID]]), "0;-0") -> SUG-0025 | B29: 46261 | C29: Karthik | E29: Build&output/ Autobuild | F29: For each auto-build domain, the conformance section currently displays values such as: DOMAIN value → DOMAIN = 'DM' STUDYID present & non-null → STUDYID populated USUBJID present & non-null → USUBJID populated Columns populated → XX% of columns have data Could we remove the text highlighted in red? In the current auto-build dataset, USUBJID is not included, so it appears with a red cross. Displaying the red text is misleading and may cause confusion. | N29: Neel will check about it. It is placeholder for now, can be removed later
A30: ="SUG-00" & TEXT(ROW() - ROW(tblSuggestions[[#Headers],[Suggestion ID]]), "0;-0") -> SUG-0026 | B30: 46261 | C30: Karthik | E30: Build&output/ Domain Build | F30: Can we add filters for the column headers of the dataset, so we can filter for DROP and focus on others ? | J30: =IF($F30="","",IF($H30="High",3,IF($H30="Medium",2,IF($H30="Low",1,0)))+IF($I30="Low",3,IF($I30="Medium",2,IF($I30="High",1,0)))) -> 0
A31: ="SUG-00" & TEXT(ROW() - ROW(tblSuggestions[[#Headers],[Suggestion ID]]), "0;-0") -> SUG-0027 | B31: 46261 | C31: Karthik | E31: Build&output/ Domain Build | F31: The column width of label is more, can we adjust the column widths ? | J31: =IF($F31="","",IF($H31="High",3,IF($H31="Medium",2,IF($H31="Low",1,0)))+IF($I31="Low",3,IF($I31="Medium",2,IF($I31="High",1,0)))) -> 0
A32: ="SUG-00" & TEXT(ROW() - ROW(tblSuggestions[[#Headers],[Suggestion ID]]), "0;-0") -> SUG-0028 | B32: 46261 | C32: Karthik | E32: Build&output/ Domain Build | F32: I tried to edit the value of STUDYID, it worked for that domain and once i scroll to another domain, the value resets to its original. Do we need to have EDIT option for these variables like STUDYID, DOMAIN? | J32: =IF($F32="","",IF($H32="High",3,IF($H32="Medium",2,IF($H32="Low",1,0)))+IF($I32="Low",3,IF($I32="Medium",2,IF($I32="High",1,0)))) -> 0
A33: ="SUG-00" & TEXT(ROW() - ROW(tblSuggestions[[#Headers],[Suggestion ID]]), "0;-0") -> SUG-0029 | B33: 46268 | C33: Karthik | E33: Mapping spec | F33: When we add another metadata file at a later stage, is it possible to integrate the previous locked mapping file and this new mapping file into the final mapping spec ? | J33: =IF($F33="","",IF($H33="High",3,IF($H33="Medium",2,IF($H33="Low",1,0)))+IF($I33="Low",3,IF($I33="Medium",2,IF($I33="High",1,0)))) -> 0
A34: ="SUG-00" & TEXT(ROW() - ROW(tblSuggestions[[#Headers],[Suggestion ID]]), "0;-0") -> SUG-0030 | J34: =IF($F34="","",IF($H34="High",3,IF($H34="Medium",2,IF($H34="Low",1,0)))+IF($I34="Low",3,IF($I34="Medium",2,IF($I34="High",1,0))))
A35: ="SUG-00" & TEXT(ROW() - ROW(tblSuggestions[[#Headers],[Suggestion ID]]), "0;-0") -> SUG-0031 | J35: =IF($F35="","",IF($H35="High",3,IF($H35="Medium",2,IF($H35="Low",1,0)))+IF($I35="Low",3,IF($I35="Medium",2,IF($I35="High",1,0))))
A36: ="SUG-00" & TEXT(ROW() - ROW(tblSuggestions[[#Headers],[Suggestion ID]]), "0;-0") -> SUG-0032 | J36: =IF($F36="","",IF($H36="High",3,IF($H36="Medium",2,IF($H36="Low",1,0)))+IF($I36="Low",3,IF($I36="Medium",2,IF($I36="High",1,0))))
A37: ="SUG-00" & TEXT(ROW() - ROW(tblSuggestions[[#Headers],[Suggestion ID]]), "0;-0") -> SUG-0033 | J37: =IF($F37="","",IF($H37="High",3,IF($H37="Medium",2,IF($H37="Low",1,0)))+IF($I37="Low",3,IF($I37="Medium",2,IF($I37="High",1,0))))
A38: ="SUG-00" & TEXT(ROW() - ROW(tblSuggestions[[#Headers],[Suggestion ID]]), "0;-0") -> SUG-0034 | J38: =IF($F38="","",IF($H38="High",3,IF($H38="Medium",2,IF($H38="Low",1,0)))+IF($I38="Low",3,IF($I38="Medium",2,IF($I38="High",1,0))))
A39: ="SUG-00" & TEXT(ROW() - ROW(tblSuggestions[[#Headers],[Suggestion ID]]), "0;-0") -> SUG-0035 | J39: =IF($F39="","",IF($H39="High",3,IF($H39="Medium",2,IF($H39="Low",1,0)))+IF($I39="Low",3,IF($I39="Medium",2,IF($I39="High",1,0))))
A40: ="SUG-00" & TEXT(ROW() - ROW(tblSuggestions[[#Headers],[Suggestion ID]]), "0;-0") -> SUG-0036 | J40: =IF($F40="","",IF($H40="High",3,IF($H40="Medium",2,IF($H40="Low",1,0)))+IF($I40="Low",3,IF($I40="Medium",2,IF($I40="High",1,0))))
A41: ="SUG-00" & TEXT(ROW() - ROW(tblSuggestions[[#Headers],[Suggestion ID]]), "0;-0") -> SUG-0037 | J41: =IF($F41="","",IF($H41="High",3,IF($H41="Medium",2,IF($H41="Low",1,0)))+IF($I41="Low",3,IF($I41="Medium",2,IF($I41="High",1,0))))
A42: ="SUG-00" & TEXT(ROW() - ROW(tblSuggestions[[#Headers],[Suggestion ID]]), "0;-0") -> SUG-0038 | J42: =IF($F42="","",IF($H42="High",3,IF($H42="Medium",2,IF($H42="Low",1,0)))+IF($I42="Low",3,IF($I42="Medium",2,IF($I42="High",1,0))))
...

Sheet UI Inventory
A1: UI Inventory
A2: Map application screens, pages and modules to requirements and open questions.
A4: Screen ID | B4: Application Area | C4: Screen / Page | D4: Primary User Roles | E4: Key Tasks | F4: Existing Pain Points | G4: Open Questions | H4: Related Requirement IDs | I4: Related Feedback IDs
A5: UI-001
A6: UI-002

Sheet Lists
A1: Priority | B1: Status | C1: Requirement Type | D1: Feedback Type | E1: Severity | F1: UI Area | G1: Effort | H1: Impact | I1: Decision | J1: Source
A2: Critical | B2: New | C2: Functional | D2: Issue | E2: Critical | F2: Navigation | G2: High | H2: High | I2: Accept | J2: User Interview
A3: High | B3: Under Review | C3: Usability | D3: Enhancement | E3: High | F3: Dashboard | G3: Medium | H3: Medium | I3: Revise | J3: Usability Test
A4: Medium | B4: Approved | C4: Accessibility | D4: Question | E4: Medium | F4: Forms/Input | G4: Low | H4: Low | I4: Defer | J4: Survey
A5: Low | B5: In Progress | C5: Performance | D5: Concern | E5: Low | F5: Search/Filter | I5: Reject | J5: Support Ticket
B6: Deferred | C6: Security | D6: Positive | F6: Workflow | I6: Needs More Info | J6: Stakeholder Review
B7: Rejected | C7: Data/Reporting | D7: Defect | F7: Reports/Exports | J7: Internal Review
B8: Completed | C8: Workflow | D8: Accessibility | F8: Notifications | J8: Other
C9: Content/Copy | D9: Usability | F9: User Profile
C10: Other | F10: Admin
F11: Buttons
F12: Other
